---
title: 데이터가 2개 이상인 경우 에러 발생했던 이유
date: 2025-02-17
categories: [issue]
tags: [python, issue]
---

### 문제
생성된 미디를 캔버스로 내보내는 작업이 계속 실패하고 있다는 상황을 공유받았다.

### 파악
Sentry를 확인해보니 `HackleUser` 객체를 생성할 때 `_id` 속성이 없어서 `KeyError` 가 발생하고 있었다. 하지만 해당 코드는 이미 기존에 다른 곳에서 사용하고 있었는데, 왜 갑자기 `_id` 가 없는 건지 의문이 생겼다.
우선은 에러가 있는 기능 관련해서 촬영 일정이 정해져 있어서 최대한 빨리 동작하게 만들어야 했다.
```python
class HackleUser(HackleEventUser):

  @classmethod
  def from_(cls, event_user: dict[str, Any]) -> Self:
    user_id = event_user.pop("_id")
    ...
```

### 시도
1. 유저 데이터 조회 시 `_id` 명시
   - 유저 데이터를 project해서 특정 값만 가져올 때 `_id` 를 명시하지 않아서, 없을 수도 있는 건가 싶었다.
   - 하지만 여전히 `KeyError` 가 발생했다.
2. 조회 결과에 `_id` 를 강제로 주입
   - 데이터 조회한 값에 `_id` 가 없다고 생각해 그럼 우선 강제로 넣어주면 될 것 같았다.
   - 하지만 여전히 동일한 에러가 발생했다. 
3. `_id` 값을 별도 메서드 인자로 전달
   - `pop` 하는 부분이 문제인 것 같아서, 메서드 호출 시 인자로 받도록 수정하고 동작 확인했다.

### 결론
해결하고 나서 편안하게 코드를 살펴보니 반복문 안에서 `HackleUser` 객체를 생성하고 있다는 것을 인지했다.
```python
def send(self) -> None:
  # hackle event user 조회
  event_user = self.user_repository.retrieve_event_user(user_id)
  
  # 반복문 돌면서 핵클 이벤트 발송
  for item in items:
    user = HackleUser.from(event_user)
  ...

# HackleUser 객체 생성 메서드
def from_(cls, event_user: dict[str, Any]) -> Self:
  user_id = event_user.pop("_id")
  ...
```

#### 파이썬의 인자 전달 방식은 `call by assignment` 다.
인자로 전달받는 객체의 자료형에 따라서 아래와 같이 동작한다.
- `mutable` 이면 `call by reference`
- `immutable` 이면 `call by value`

여기서 `event_user` 가 dict 자료형이여서 `call by reference` 로 다뤄졌다. 따라서 `pop` 을 하게 되면 원본 값이 수정되기 때문에 두 번째 반복문에서는 값에 `_id` 가 없어 `KeyError` 가 발생했던 거였다.

### 회고
동일 코드로 다른 기능들에서 문제가 없었던 이유는 단일 데이터를 보내는 작업이었기 때문에 문제가 없었다. 일정이 촉박하더라도 좀 더 차분히 디버깅 하면서 코드를 봤으면 배포 여러 번 하지 않고 고칠 수 있었을 것 같은데, 우선 동작하게 만들어 놓으려다 보니까 어디가 문제인지 몰라 결국 더 오래 걸렸던 것 같다.
코드 리뷰 하면서도 놓친 부분이여서, 기억해두고 고려해야겠다.
